{
 "cells": [
  {
   "cell_type": "code",
   "execution_count": 1,
   "metadata": {},
   "outputs": [
    {
     "name": "stdout",
     "output_type": "stream",
     "text": [
      "Found 20579 files belonging to 2 classes.\n",
      "Using 18522 files for training.\n",
      "Using 2057 files for validation.\n"
     ]
    }
   ],
   "source": [
    "\n",
    "import tensorflow as tf\n",
    "from tensorflow import keras\n",
    "\n",
    "dataset_path = \"/Users/ajinkya/Documents/Visual Studio Code/0_PROJECTS/kaggle_dog_breed/src/dataset/dog-breed-imagefolder\"\n",
    "training_dataset, validation_dataset = tf.keras.utils.image_dataset_from_directory(dataset_path, \n",
    "                                            image_size = (224, 224),  # Default value is (256, 256). **source of potential error**\n",
    "                                            validation_split = 0.1, subset = \"both\", seed = 10, # Need to set subset & seed both for validation_split\n",
    "                                            batch_size = 32, shuffle= True, # Default values used automatically. **SOURCE OF POTENTIAL ERROR**\n",
    "                                            color_mode = \"rgb\") # Channels = 3. Hidden from us"
   ]
  },
  {
   "cell_type": "code",
   "execution_count": 7,
   "metadata": {},
   "outputs": [
    {
     "name": "stderr",
     "output_type": "stream",
     "text": [
      "WARNING:absl:At this time, the v2.11+ optimizer `tf.keras.optimizers.Adam` runs slowly on M1/M2 Macs, please use the legacy Keras optimizer instead, located at `tf.keras.optimizers.legacy.Adam`.\n"
     ]
    }
   ],
   "source": [
    "NUM_CLASSES = 120\n",
    "\n",
    "class simple_fcnn(keras.Model):\n",
    "    def __init__(self):\n",
    "        super().__init__()\n",
    "\n",
    "        self.internal_model = tf.keras.models.Sequential([\n",
    "            keras.layers.Input(shape = (224, 224, 3)),\n",
    "            keras.layers.Flatten(),\n",
    "            keras.layers.Dense(units = 240, activation=\"relu\", ),\n",
    "            keras.layers.Dense(units = NUM_CLASSES),\n",
    "        ])\n",
    "\n",
    "    def call(self, input_single_batch):\n",
    "        final_layer_output = self.internal_model(input_single_batch)\n",
    "\n",
    "        return final_layer_output\n",
    "\n",
    "model  = simple_fcnn()\n",
    "model.compile(\n",
    "    loss      = keras.losses.CategoricalCrossentropy(),\n",
    "    optimizer = keras.optimizers.Adam() \n",
    ")"
   ]
  },
  {
   "cell_type": "code",
   "execution_count": 18,
   "metadata": {},
   "outputs": [],
   "source": [
    "x, y = next(iter(training_dataset))"
   ]
  },
  {
   "cell_type": "code",
   "execution_count": 20,
   "metadata": {},
   "outputs": [
    {
     "data": {
      "text/plain": [
       "<tf.Tensor: shape=(32,), dtype=int32, numpy=\n",
       "array([0, 0, 0, 0, 0, 0, 0, 0, 1, 0, 1, 0, 1, 0, 1, 0, 1, 0, 1, 1, 0, 0,\n",
       "       0, 1, 1, 1, 1, 1, 0, 0, 0, 1], dtype=int32)>"
      ]
     },
     "execution_count": 20,
     "metadata": {},
     "output_type": "execute_result"
    }
   ],
   "source": [
    "y"
   ]
  },
  {
   "cell_type": "code",
   "execution_count": 23,
   "metadata": {},
   "outputs": [
    {
     "data": {
      "text/plain": [
       "TensorShape([32])"
      ]
     },
     "execution_count": 23,
     "metadata": {},
     "output_type": "execute_result"
    }
   ],
   "source": [
    "y.shape"
   ]
  },
  {
   "cell_type": "code",
   "execution_count": 8,
   "metadata": {},
   "outputs": [
    {
     "ename": "ValueError",
     "evalue": "in user code:\n\n    File \"/Users/ajinkya/anaconda3/lib/python3.11/site-packages/keras/src/engine/training.py\", line 1401, in train_function  *\n        return step_function(self, iterator)\n    File \"/Users/ajinkya/anaconda3/lib/python3.11/site-packages/keras/src/engine/training.py\", line 1384, in step_function  **\n        outputs = model.distribute_strategy.run(run_step, args=(data,))\n    File \"/Users/ajinkya/anaconda3/lib/python3.11/site-packages/keras/src/engine/training.py\", line 1373, in run_step  **\n        outputs = model.train_step(data)\n    File \"/Users/ajinkya/anaconda3/lib/python3.11/site-packages/keras/src/engine/training.py\", line 1151, in train_step\n        loss = self.compute_loss(x, y, y_pred, sample_weight)\n    File \"/Users/ajinkya/anaconda3/lib/python3.11/site-packages/keras/src/engine/training.py\", line 1209, in compute_loss\n        return self.compiled_loss(\n    File \"/Users/ajinkya/anaconda3/lib/python3.11/site-packages/keras/src/engine/compile_utils.py\", line 277, in __call__\n        loss_value = loss_obj(y_t, y_p, sample_weight=sw)\n    File \"/Users/ajinkya/anaconda3/lib/python3.11/site-packages/keras/src/losses.py\", line 143, in __call__\n        losses = call_fn(y_true, y_pred)\n    File \"/Users/ajinkya/anaconda3/lib/python3.11/site-packages/keras/src/losses.py\", line 270, in call  **\n        return ag_fn(y_true, y_pred, **self._fn_kwargs)\n    File \"/Users/ajinkya/anaconda3/lib/python3.11/site-packages/keras/src/losses.py\", line 2221, in categorical_crossentropy\n        return backend.categorical_crossentropy(\n    File \"/Users/ajinkya/anaconda3/lib/python3.11/site-packages/keras/src/backend.py\", line 5573, in categorical_crossentropy\n        target.shape.assert_is_compatible_with(output.shape)\n\n    ValueError: Shapes (None, 1) and (None, 120) are incompatible\n",
     "output_type": "error",
     "traceback": [
      "\u001b[0;31m---------------------------------------------------------------------------\u001b[0m",
      "\u001b[0;31mValueError\u001b[0m                                Traceback (most recent call last)",
      "Cell \u001b[0;32mIn[8], line 1\u001b[0m\n\u001b[0;32m----> 1\u001b[0m model\u001b[38;5;241m.\u001b[39mfit(training_dataset)\n",
      "File \u001b[0;32m~/anaconda3/lib/python3.11/site-packages/keras/src/utils/traceback_utils.py:70\u001b[0m, in \u001b[0;36mfilter_traceback.<locals>.error_handler\u001b[0;34m(*args, **kwargs)\u001b[0m\n\u001b[1;32m     67\u001b[0m     filtered_tb \u001b[38;5;241m=\u001b[39m _process_traceback_frames(e\u001b[38;5;241m.\u001b[39m__traceback__)\n\u001b[1;32m     68\u001b[0m     \u001b[38;5;66;03m# To get the full stack trace, call:\u001b[39;00m\n\u001b[1;32m     69\u001b[0m     \u001b[38;5;66;03m# `tf.debugging.disable_traceback_filtering()`\u001b[39;00m\n\u001b[0;32m---> 70\u001b[0m     \u001b[38;5;28;01mraise\u001b[39;00m e\u001b[38;5;241m.\u001b[39mwith_traceback(filtered_tb) \u001b[38;5;28;01mfrom\u001b[39;00m \u001b[38;5;28;01mNone\u001b[39;00m\n\u001b[1;32m     71\u001b[0m \u001b[38;5;28;01mfinally\u001b[39;00m:\n\u001b[1;32m     72\u001b[0m     \u001b[38;5;28;01mdel\u001b[39;00m filtered_tb\n",
      "File \u001b[0;32m/var/folders/yc/sdgc0ftj32z_ctpgsn9ynz440000gn/T/__autograph_generated_filerih8uvx0.py:15\u001b[0m, in \u001b[0;36mouter_factory.<locals>.inner_factory.<locals>.tf__train_function\u001b[0;34m(iterator)\u001b[0m\n\u001b[1;32m     13\u001b[0m \u001b[38;5;28;01mtry\u001b[39;00m:\n\u001b[1;32m     14\u001b[0m     do_return \u001b[38;5;241m=\u001b[39m \u001b[38;5;28;01mTrue\u001b[39;00m\n\u001b[0;32m---> 15\u001b[0m     retval_ \u001b[38;5;241m=\u001b[39m ag__\u001b[38;5;241m.\u001b[39mconverted_call(ag__\u001b[38;5;241m.\u001b[39mld(step_function), (ag__\u001b[38;5;241m.\u001b[39mld(\u001b[38;5;28mself\u001b[39m), ag__\u001b[38;5;241m.\u001b[39mld(iterator)), \u001b[38;5;28;01mNone\u001b[39;00m, fscope)\n\u001b[1;32m     16\u001b[0m \u001b[38;5;28;01mexcept\u001b[39;00m:\n\u001b[1;32m     17\u001b[0m     do_return \u001b[38;5;241m=\u001b[39m \u001b[38;5;28;01mFalse\u001b[39;00m\n",
      "\u001b[0;31mValueError\u001b[0m: in user code:\n\n    File \"/Users/ajinkya/anaconda3/lib/python3.11/site-packages/keras/src/engine/training.py\", line 1401, in train_function  *\n        return step_function(self, iterator)\n    File \"/Users/ajinkya/anaconda3/lib/python3.11/site-packages/keras/src/engine/training.py\", line 1384, in step_function  **\n        outputs = model.distribute_strategy.run(run_step, args=(data,))\n    File \"/Users/ajinkya/anaconda3/lib/python3.11/site-packages/keras/src/engine/training.py\", line 1373, in run_step  **\n        outputs = model.train_step(data)\n    File \"/Users/ajinkya/anaconda3/lib/python3.11/site-packages/keras/src/engine/training.py\", line 1151, in train_step\n        loss = self.compute_loss(x, y, y_pred, sample_weight)\n    File \"/Users/ajinkya/anaconda3/lib/python3.11/site-packages/keras/src/engine/training.py\", line 1209, in compute_loss\n        return self.compiled_loss(\n    File \"/Users/ajinkya/anaconda3/lib/python3.11/site-packages/keras/src/engine/compile_utils.py\", line 277, in __call__\n        loss_value = loss_obj(y_t, y_p, sample_weight=sw)\n    File \"/Users/ajinkya/anaconda3/lib/python3.11/site-packages/keras/src/losses.py\", line 143, in __call__\n        losses = call_fn(y_true, y_pred)\n    File \"/Users/ajinkya/anaconda3/lib/python3.11/site-packages/keras/src/losses.py\", line 270, in call  **\n        return ag_fn(y_true, y_pred, **self._fn_kwargs)\n    File \"/Users/ajinkya/anaconda3/lib/python3.11/site-packages/keras/src/losses.py\", line 2221, in categorical_crossentropy\n        return backend.categorical_crossentropy(\n    File \"/Users/ajinkya/anaconda3/lib/python3.11/site-packages/keras/src/backend.py\", line 5573, in categorical_crossentropy\n        target.shape.assert_is_compatible_with(output.shape)\n\n    ValueError: Shapes (None, 1) and (None, 120) are incompatible\n"
     ]
    }
   ],
   "source": [
    "model.fit(training_dataset)"
   ]
  },
  {
   "cell_type": "code",
   "execution_count": null,
   "metadata": {},
   "outputs": [],
   "source": []
  }
 ],
 "metadata": {
  "kernelspec": {
   "display_name": "Python 3",
   "language": "python",
   "name": "python3"
  },
  "language_info": {
   "codemirror_mode": {
    "name": "ipython",
    "version": 3
   },
   "file_extension": ".py",
   "mimetype": "text/x-python",
   "name": "python",
   "nbconvert_exporter": "python",
   "pygments_lexer": "ipython3",
   "version": "3.11.5"
  }
 },
 "nbformat": 4,
 "nbformat_minor": 2
}
